[2023-05-23T17:49:24.715+0000] {taskinstance.py:1084} INFO - Dependencies all met for dep_context=non-requeueable deps ti=<TaskInstance: refresh_token.ETL manual__2023-05-23T17:36:29.595804+00:00 [queued]>
[2023-05-23T17:49:24.732+0000] {taskinstance.py:1084} INFO - Dependencies all met for dep_context=requeueable deps ti=<TaskInstance: refresh_token.ETL manual__2023-05-23T17:36:29.595804+00:00 [queued]>
[2023-05-23T17:49:24.732+0000] {taskinstance.py:1282} INFO - 
--------------------------------------------------------------------------------
[2023-05-23T17:49:24.732+0000] {taskinstance.py:1283} INFO - Starting attempt 1 of 6
[2023-05-23T17:49:24.732+0000] {taskinstance.py:1284} INFO - 
--------------------------------------------------------------------------------
[2023-05-23T17:49:24.762+0000] {taskinstance.py:1303} INFO - Executing <Task(PythonOperator): ETL> on 2023-05-23 17:36:29.595804+00:00
[2023-05-23T17:49:24.774+0000] {standard_task_runner.py:55} INFO - Started process 3260 to run task
[2023-05-23T17:49:24.781+0000] {standard_task_runner.py:82} INFO - Running: ['***', 'tasks', 'run', 'refresh_token', 'ETL', 'manual__2023-05-23T17:36:29.595804+00:00', '--job-id', '58', '--raw', '--subdir', 'DAGS_FOLDER/refresh_token_DAG.py', '--cfg-path', '/tmp/tmpfy3oqh42']
[2023-05-23T17:49:24.783+0000] {standard_task_runner.py:83} INFO - Job 58: Subtask ETL
[2023-05-23T17:49:24.886+0000] {task_command.py:388} INFO - Running <TaskInstance: refresh_token.ETL manual__2023-05-23T17:36:29.595804+00:00 [running]> on host 2a789c3fa429
[2023-05-23T17:49:25.023+0000] {taskinstance.py:1511} INFO - Exporting the following env vars:
AIRFLOW_CTX_DAG_OWNER=fox
AIRFLOW_CTX_DAG_ID=refresh_token
AIRFLOW_CTX_TASK_ID=ETL
AIRFLOW_CTX_EXECUTION_DATE=2023-05-23T17:36:29.595804+00:00
AIRFLOW_CTX_TRY_NUMBER=1
AIRFLOW_CTX_DAG_RUN_ID=manual__2023-05-23T17:36:29.595804+00:00
[2023-05-23T17:49:25.323+0000] {taskinstance.py:1775} ERROR - Task failed with exception
Traceback (most recent call last):
  File "/home/airflow/.local/lib/python3.7/site-packages/airflow/operators/python.py", line 175, in execute
    return_value = self.execute_callable()
  File "/home/airflow/.local/lib/python3.7/site-packages/airflow/operators/python.py", line 192, in execute_callable
    return self.python_callable(*self.op_args, **self.op_kwargs)
  File "/opt/airflow/dags/Spotify_ETL.py", line 61, in run_spotify_etl
    for song in resource['items']:
KeyError: 'items'
[2023-05-23T17:49:25.334+0000] {taskinstance.py:1326} INFO - Marking task as UP_FOR_RETRY. dag_id=refresh_token, task_id=ETL, execution_date=20230523T173629, start_date=20230523T174924, end_date=20230523T174925
[2023-05-23T17:49:25.360+0000] {standard_task_runner.py:105} ERROR - Failed to execute job 58 for task ETL ('items'; 3260)
[2023-05-23T17:49:25.395+0000] {local_task_job.py:212} INFO - Task exited with return code 1
[2023-05-23T17:49:25.426+0000] {taskinstance.py:2585} INFO - 0 downstream tasks scheduled from follow-on schedule check
