[2023-06-05T17:36:52.181+0000] {taskinstance.py:1084} INFO - Dependencies all met for dep_context=non-requeueable deps ti=<TaskInstance: weather.add_data_in_weather scheduled__2023-05-21T08:01:00+00:00 [queued]>
[2023-06-05T17:36:52.275+0000] {taskinstance.py:1084} INFO - Dependencies all met for dep_context=requeueable deps ti=<TaskInstance: weather.add_data_in_weather scheduled__2023-05-21T08:01:00+00:00 [queued]>
[2023-06-05T17:36:52.279+0000] {taskinstance.py:1282} INFO - 
--------------------------------------------------------------------------------
[2023-06-05T17:36:52.279+0000] {taskinstance.py:1283} INFO - Starting attempt 1 of 6
[2023-06-05T17:36:52.280+0000] {taskinstance.py:1284} INFO - 
--------------------------------------------------------------------------------
[2023-06-05T17:36:52.404+0000] {taskinstance.py:1303} INFO - Executing <Task(PostgresOperator): add_data_in_weather> on 2023-05-21 08:01:00+00:00
[2023-06-05T17:36:52.439+0000] {standard_task_runner.py:55} INFO - Started process 11194 to run task
[2023-06-05T17:36:52.443+0000] {standard_task_runner.py:82} INFO - Running: ['***', 'tasks', 'run', 'weather', 'add_data_in_weather', 'scheduled__2023-05-21T08:01:00+00:00', '--job-id', '498', '--raw', '--subdir', 'DAGS_FOLDER/weather_DAG.py', '--cfg-path', '/tmp/tmpv7na995a']
[2023-06-05T17:36:52.450+0000] {standard_task_runner.py:83} INFO - Job 498: Subtask add_data_in_weather
[2023-06-05T17:36:52.956+0000] {task_command.py:388} INFO - Running <TaskInstance: weather.add_data_in_weather scheduled__2023-05-21T08:01:00+00:00 [running]> on host 05172cfd5782
[2023-06-05T17:36:53.242+0000] {abstractoperator.py:615} ERROR - Exception rendering Jinja template for task 'add_data_in_weather', field 'sql'. Template: "\n            insert into weather_data (date, current_temperature, feels_like, sky, chance_of_precipitation, wind, \n            pressure, uv_index, humidity, precipitation) values \n            ('{{ti.xcom_pull(task_ids='scraping weather')[0]}}',\n            '{{ti.xcom_pull(task_ids='scraping weather')[1]}}',\n            '{{ti.xcom_pull(task_ids='scraping weather')[2]}}',\n            '{{ti.xcom_pull(task_ids='scraping weather')[3]}}'\n            )\n            "
Traceback (most recent call last):
  File "/home/airflow/.local/lib/python3.7/site-packages/airflow/models/abstractoperator.py", line 607, in _do_render_template_fields
    seen_oids,
  File "/home/airflow/.local/lib/python3.7/site-packages/airflow/models/abstractoperator.py", line 665, in render_template
    return render_template_to_string(template, context)
  File "/home/airflow/.local/lib/python3.7/site-packages/airflow/utils/helpers.py", line 288, in render_template_to_string
    return render_template(template, cast(MutableMapping[str, Any], context), native=False)
  File "/home/airflow/.local/lib/python3.7/site-packages/airflow/utils/helpers.py", line 283, in render_template
    return "".join(nodes)
  File "<template>", line 13, in root
  File "/home/airflow/.local/lib/python3.7/site-packages/jinja2/runtime.py", line 852, in _fail_with_undefined_error
    raise self._undefined_exception(self._undefined_message)
jinja2.exceptions.UndefinedError: None has no element 0
[2023-06-05T17:36:53.253+0000] {taskinstance.py:1775} ERROR - Task failed with exception
Traceback (most recent call last):
  File "/home/airflow/.local/lib/python3.7/site-packages/airflow/models/taskinstance.py", line 1377, in _run_raw_task
    self._execute_task_with_callbacks(context, test_mode)
  File "/home/airflow/.local/lib/python3.7/site-packages/airflow/models/taskinstance.py", line 1495, in _execute_task_with_callbacks
    task_orig = self.render_templates(context=context)
  File "/home/airflow/.local/lib/python3.7/site-packages/airflow/models/taskinstance.py", line 2122, in render_templates
    original_task.render_template_fields(context)
  File "/home/airflow/.local/lib/python3.7/site-packages/airflow/models/baseoperator.py", line 1179, in render_template_fields
    self._do_render_template_fields(self, self.template_fields, context, jinja_env, set())
  File "/home/airflow/.local/lib/python3.7/site-packages/airflow/utils/session.py", line 75, in wrapper
    return func(*args, session=session, **kwargs)
  File "/home/airflow/.local/lib/python3.7/site-packages/airflow/models/abstractoperator.py", line 607, in _do_render_template_fields
    seen_oids,
  File "/home/airflow/.local/lib/python3.7/site-packages/airflow/models/abstractoperator.py", line 665, in render_template
    return render_template_to_string(template, context)
  File "/home/airflow/.local/lib/python3.7/site-packages/airflow/utils/helpers.py", line 288, in render_template_to_string
    return render_template(template, cast(MutableMapping[str, Any], context), native=False)
  File "/home/airflow/.local/lib/python3.7/site-packages/airflow/utils/helpers.py", line 283, in render_template
    return "".join(nodes)
  File "<template>", line 13, in root
  File "/home/airflow/.local/lib/python3.7/site-packages/jinja2/runtime.py", line 852, in _fail_with_undefined_error
    raise self._undefined_exception(self._undefined_message)
jinja2.exceptions.UndefinedError: None has no element 0
[2023-06-05T17:36:53.302+0000] {taskinstance.py:1326} INFO - Marking task as UP_FOR_RETRY. dag_id=weather, task_id=add_data_in_weather, execution_date=20230521T080100, start_date=20230605T173652, end_date=20230605T173653
[2023-06-05T17:36:53.382+0000] {standard_task_runner.py:105} ERROR - Failed to execute job 498 for task add_data_in_weather (None has no element 0; 11194)
[2023-06-05T17:36:53.466+0000] {local_task_job.py:212} INFO - Task exited with return code 1
[2023-06-05T17:36:54.099+0000] {taskinstance.py:2585} INFO - 0 downstream tasks scheduled from follow-on schedule check
