[2023-06-05T18:10:53.893+0000] {taskinstance.py:1084} INFO - Dependencies all met for dep_context=non-requeueable deps ti=<TaskInstance: weather.add_data_in_weather manual__2023-06-05T18:10:47.819881+00:00 [queued]>
[2023-06-05T18:10:53.909+0000] {taskinstance.py:1084} INFO - Dependencies all met for dep_context=requeueable deps ti=<TaskInstance: weather.add_data_in_weather manual__2023-06-05T18:10:47.819881+00:00 [queued]>
[2023-06-05T18:10:53.909+0000] {taskinstance.py:1282} INFO - 
--------------------------------------------------------------------------------
[2023-06-05T18:10:53.910+0000] {taskinstance.py:1283} INFO - Starting attempt 1 of 6
[2023-06-05T18:10:53.910+0000] {taskinstance.py:1284} INFO - 
--------------------------------------------------------------------------------
[2023-06-05T18:10:53.931+0000] {taskinstance.py:1303} INFO - Executing <Task(PostgresOperator): add_data_in_weather> on 2023-06-05 18:10:47.819881+00:00
[2023-06-05T18:10:53.937+0000] {standard_task_runner.py:55} INFO - Started process 13070 to run task
[2023-06-05T18:10:53.940+0000] {standard_task_runner.py:82} INFO - Running: ['***', 'tasks', 'run', 'weather', 'add_data_in_weather', 'manual__2023-06-05T18:10:47.819881+00:00', '--job-id', '867', '--raw', '--subdir', 'DAGS_FOLDER/weather_DAG.py', '--cfg-path', '/tmp/tmptb3wk8kf']
[2023-06-05T18:10:53.942+0000] {standard_task_runner.py:83} INFO - Job 867: Subtask add_data_in_weather
[2023-06-05T18:10:54.024+0000] {task_command.py:388} INFO - Running <TaskInstance: weather.add_data_in_weather manual__2023-06-05T18:10:47.819881+00:00 [running]> on host 05172cfd5782
[2023-06-05T18:10:54.267+0000] {taskinstance.py:1511} INFO - Exporting the following env vars:
AIRFLOW_CTX_DAG_OWNER=fox
AIRFLOW_CTX_DAG_ID=weather
AIRFLOW_CTX_TASK_ID=add_data_in_weather
AIRFLOW_CTX_EXECUTION_DATE=2023-06-05T18:10:47.819881+00:00
AIRFLOW_CTX_TRY_NUMBER=1
AIRFLOW_CTX_DAG_RUN_ID=manual__2023-06-05T18:10:47.819881+00:00
[2023-06-05T18:10:54.268+0000] {sql.py:254} INFO - Executing: 
            insert into weather_data (date, current_temperature, feels_like, sky, chance_of_precipitation, wind, 
            pressure, uv_index, humidity, precipitation, timestamps) values 
            ('2023-06-05T20:05:52+02:00',
            '+17째',
            '+18째C',
            'Overcast, no precipitation',
            '40',
            '2',
            '741',
            '0/12',
            '69',
            '0.01',
            '2023-06-05'
            )
            
[2023-06-05T18:10:54.280+0000] {base.py:73} INFO - Using connection ID 'postgres_localhost' for task execution.
[2023-06-05T18:10:54.717+0000] {base.py:73} INFO - Using connection ID 'postgres_localhost' for task execution.
[2023-06-05T18:10:54.721+0000] {sql.py:375} INFO - Running statement: 
            insert into weather_data (date, current_temperature, feels_like, sky, chance_of_precipitation, wind, 
            pressure, uv_index, humidity, precipitation, timestamps) values 
            ('2023-06-05T20:05:52+02:00',
            '+17째',
            '+18째C',
            'Overcast, no precipitation',
            '40',
            '2',
            '741',
            '0/12',
            '69',
            '0.01',
            '2023-06-05'
            )
            , parameters: None
[2023-06-05T18:10:54.725+0000] {taskinstance.py:1775} ERROR - Task failed with exception
Traceback (most recent call last):
  File "/home/airflow/.local/lib/python3.7/site-packages/airflow/providers/common/sql/operators/sql.py", line 266, in execute
    **extra_kwargs,
  File "/home/airflow/.local/lib/python3.7/site-packages/airflow/providers/common/sql/hooks/sql.py", line 349, in run
    self._run_command(cur, sql_statement, parameters)
  File "/home/airflow/.local/lib/python3.7/site-packages/airflow/providers/common/sql/hooks/sql.py", line 380, in _run_command
    cur.execute(sql_statement)
psycopg2.errors.UndefinedColumn: column "timestamps" of relation "weather_data" does not exist
LINE 3: ...     pressure, uv_index, humidity, precipitation, timestamps...
                                                             ^

[2023-06-05T18:10:54.737+0000] {taskinstance.py:1326} INFO - Marking task as UP_FOR_RETRY. dag_id=weather, task_id=add_data_in_weather, execution_date=20230605T181047, start_date=20230605T181053, end_date=20230605T181054
[2023-06-05T18:10:54.758+0000] {standard_task_runner.py:105} ERROR - Failed to execute job 867 for task add_data_in_weather (column "timestamps" of relation "weather_data" does not exist
LINE 3: ...     pressure, uv_index, humidity, precipitation, timestamps...
                                                             ^
; 13070)
[2023-06-05T18:10:54.801+0000] {local_task_job.py:212} INFO - Task exited with return code 1
[2023-06-05T18:10:54.831+0000] {taskinstance.py:2585} INFO - 0 downstream tasks scheduled from follow-on schedule check
